<?xml version='1.0'?>

<robot name="robot" xmlns:xacro="http://www.ros.org/wiki/xacro" >

  <xacro:property name="dlzka" value="0.4"/>
  <xacro:property name="sirka" value="0.2"/>
  <xacro:property name="vyska" value="0.1"/>
  <xacro:property name="rkolesa" value="0.1"/>
  <xacro:property name="hkolesa" value="0.05"/>

  <material name="black">
    <color rgba="0.0 0.0 0.0 1.0"/>
  </material>
  <material name="blue">
    <color rgba="0.203125 0.23828125 0.28515625 1.0"/>
  </material>
  <material name="green">
    <color rgba="0.0 0.8 0.0 1.0"/>
  </material>
  <material name="grey">
    <color rgba="0.2 0.2 0.2 1.0"/>
  </material>
  <material name="orange">
    <color rgba="1.0 0.423529411765 0.0392156862745 1.0"/>
  </material>
  <material name="brown">
    <color rgba="0.870588235294 0.811764705882 0.764705882353 1.0"/>
  </material>
  <material name="red">
    <color rgba="0.80078125 0.12890625 0.1328125 1.0"/>
  </material>
  <material name="white">
    <color rgba="1.0 1.0 1.0 1.0"/>
  </material>

  <link name='telo'>
    <!--pose>0 0 0.1 0 0 0</pose-->
    <visual name='telo_visual'>
      <origin xyz="0 0 0.1" rpy="0 0 0"/>
      <geometry>
        <box size="${dlzka} ${sirka} ${vyska}"/>
      </geometry>
      <material name="orange"/>
    </visual>
    <collision name='telo_collision'>
      <geometry>
        <box size="${dlzka} ${sirka} ${vyska}"/>
      </geometry>
    </collision>
    <inertial>
      <mass value="10.0"/>
      <origin xyz="0.0 0 0.1" rpy="0 0 0"/>
      <inertia
              ixx="0.5" ixy="0" ixz="0"
              iyy="1.0" iyz="0"
              izz="0.1"
      />
    </inertial>
  </link>


  <link name="vsesmerove_koleso">
    <visual name='vsesmerove_visual'>
      <origin xyz="0 0 0" rpy="0 0 0"/>
      <geometry>
        <sphere radius="0.05"/>
      </geometry>
      <material name="blue"/>
    </visual>
    <collision name='vsesmerove_collision'>
      <origin xyz="-0.15 0 -0.05" rpy="0 0 0"/>
      <geometry>
        <sphere radius="0.05"/>
      </geometry>
      <surface>
        <friction>
          <ode>
            <mu>0</mu>
            <mu2>0</mu2>
            <slip1>1.0</slip1>
            <slip2>1.0</slip2>
          </ode>
        </friction>
      </surface>
    </collision>
  </link>


  <joint name="vsesmerove_koleso_upevnenie" type="fixed">
    <origin xyz="-0.15 0 -0.05" rpy="0 0 0"/>
    <parent link="telo"/>
    <child link="vsesmerove_koleso"/>
  </joint>

  <!-- kolesa robota  -->
  <xacro:macro name="koleso" params="prefix reflect">

    <link name="${prefix}_koleso">
      <visual name="${prefix}_koleso_visual">
        <origin xyz="0 0 0" rpy="0 1.5707 1.5707"/>
        <geometry>
          <cylinder radius="${rkolesa}" length="${hkolesa}"/>
        </geometry>
        <material name="red"/>
      </visual>
      <collision name="${prefix}_koleso_collision">
        <origin xyz="0 0 0" rpy="0 1.5707 1.5707"/>
        <geometry>
          <cylinder radius="${rkolesa}" length="${hkolesa}"/>
        </geometry>
      </collision>
      <inertial>
        <origin xyz="0 0 0" rpy="0 1.5707 1.5707"/>
        <mass value="5"/>
        <cylinder_inertia m="5" r="0.1" h="0.05"/>
        <inertia
                ixx="1.0" ixy="0.0" ixz="0.0"
                iyy="1.0" iyz="0.0"
                izz="1.0"/>
      </inertial>
    </link>

    <joint type="continuous" name="${prefix}_koleso_zaves">
      <origin xyz="0.1 ${reflect*0.125} 0" rpy="0 0 0"/>
      <child link="${prefix}_koleso"/>
      <parent link="telo"/>
      <axis xyz="0 1 0" rpy="0 0 0"/>
      <limit effort="100" velocity="100"/>
      <joint_properties damping="0.0" friction="0.0"/>
    </joint>

    <transmission name="${prefix}_koleso_trans">
      <type>transmission_interface/SimpleTransmission</type>
      <actuator name="${prefix}_koleso_motor">
        <!--v navode bolo 10 -->
        <mechanicalReduction>1</mechanicalReduction>
        <hardwareInterface>hardware_interface/VelocityJointInterface</hardwareInterface>
      </actuator>
    </transmission>

  </xacro:macro>
  <xacro:koleso prefix="lave" reflect="-1"/>
  <xacro:koleso prefix="prave" reflect="1"/>

  <link name="nas_lidar">
    <inertial>
      <mass value="0.001"/>
      <origin xyz="0 0 0" rpy="0 0 0"/>
      <inertia ixx="0.0001" ixy="0" ixz="0" iyy="0.0001" iyz="0" izz="0.0001"/>
    </inertial>
    <visual>
      <origin xyz="0 0 0" rpy="0 0 0"/>
      <geometry>
        <box size="0.05 0.05 0.02"/>
      </geometry>
      <material name="red"/>
    </visual>
    <collision>
      <origin xyz="0 0 0" rpy="0 0 0"/>
      <geometry>
        <box size="0.05 0.05 0.02"/>
      </geometry>
    </collision>
  </link>

  <joint name="nas_lidar_upevnenie" type="fixed">
    <origin xyz="0.1 0 0.1" rpy="0 0 0"/>
    <parent link="telo"/>
    <child link="nas_lidar"/>
    <axis xyz="0 1 0"/>
  </joint>

</robot>
